[2024-05-10T15:52:22.822+0000] {processor.py:161} INFO - Started process (PID=226) to work on /opt/airflow/dags/my_first_dag.py
[2024-05-10T15:52:22.826+0000] {processor.py:830} INFO - Processing file /opt/airflow/dags/my_first_dag.py for tasks to queue
[2024-05-10T15:52:22.849+0000] {logging_mixin.py:188} INFO - [2024-05-10T15:52:22.845+0000] {dagbag.py:545} INFO - Filling up the DagBag from /opt/airflow/dags/my_first_dag.py
[2024-05-10T15:52:22.888+0000] {logging_mixin.py:188} INFO - [2024-05-10T15:52:22.878+0000] {dagbag.py:355} ERROR - Failed to import: /opt/airflow/dags/my_first_dag.py
Traceback (most recent call last):
  File "/home/airflow/.local/lib/python3.12/site-packages/airflow/models/dagbag.py", line 351, in parse
    loader.exec_module(new_module)
  File "<frozen importlib._bootstrap_external>", line 995, in exec_module
  File "<frozen importlib._bootstrap>", line 488, in _call_with_frames_removed
  File "/opt/airflow/dags/my_first_dag.py", line 9, in <module>
    with DAG(dag_id  = 'my_first_dag',
         ^^^^^^^^^^^^^^^^^^^^^^^^^^^^^
TypeError: DAG.__init__() got an unexpected keyword argument 'scheduler_interval'
[2024-05-10T15:52:22.891+0000] {processor.py:842} WARNING - No viable dags retrieved from /opt/airflow/dags/my_first_dag.py
[2024-05-10T15:52:22.936+0000] {processor.py:183} INFO - Processing /opt/airflow/dags/my_first_dag.py took 0.140 seconds
[2024-05-10T15:52:49.072+0000] {processor.py:161} INFO - Started process (PID=237) to work on /opt/airflow/dags/my_first_dag.py
[2024-05-10T15:52:49.074+0000] {processor.py:830} INFO - Processing file /opt/airflow/dags/my_first_dag.py for tasks to queue
[2024-05-10T15:52:49.078+0000] {logging_mixin.py:188} INFO - [2024-05-10T15:52:49.078+0000] {dagbag.py:545} INFO - Filling up the DagBag from /opt/airflow/dags/my_first_dag.py
[2024-05-10T15:52:49.093+0000] {logging_mixin.py:188} INFO - [2024-05-10T15:52:49.089+0000] {dagbag.py:355} ERROR - Failed to import: /opt/airflow/dags/my_first_dag.py
Traceback (most recent call last):
  File "/home/airflow/.local/lib/python3.12/site-packages/airflow/models/dagbag.py", line 351, in parse
    loader.exec_module(new_module)
  File "<frozen importlib._bootstrap_external>", line 995, in exec_module
  File "<frozen importlib._bootstrap>", line 488, in _call_with_frames_removed
  File "/opt/airflow/dags/my_first_dag.py", line 9, in <module>
    with DAG(dag_id  = 'my_first_dag',
         ^^^^^^^^^^^^^^^^^^^^^^^^^^^^^
TypeError: DAG.__init__() got an unexpected keyword argument 'scheduler_interval'
[2024-05-10T15:52:49.094+0000] {processor.py:842} WARNING - No viable dags retrieved from /opt/airflow/dags/my_first_dag.py
[2024-05-10T15:52:49.128+0000] {processor.py:183} INFO - Processing /opt/airflow/dags/my_first_dag.py took 0.065 seconds
[2024-05-10T15:53:19.702+0000] {processor.py:161} INFO - Started process (PID=248) to work on /opt/airflow/dags/my_first_dag.py
[2024-05-10T15:53:19.718+0000] {processor.py:830} INFO - Processing file /opt/airflow/dags/my_first_dag.py for tasks to queue
[2024-05-10T15:53:19.725+0000] {logging_mixin.py:188} INFO - [2024-05-10T15:53:19.724+0000] {dagbag.py:545} INFO - Filling up the DagBag from /opt/airflow/dags/my_first_dag.py
[2024-05-10T15:53:19.735+0000] {logging_mixin.py:188} INFO - [2024-05-10T15:53:19.732+0000] {dagbag.py:355} ERROR - Failed to import: /opt/airflow/dags/my_first_dag.py
Traceback (most recent call last):
  File "/home/airflow/.local/lib/python3.12/site-packages/airflow/models/dagbag.py", line 351, in parse
    loader.exec_module(new_module)
  File "<frozen importlib._bootstrap_external>", line 995, in exec_module
  File "<frozen importlib._bootstrap>", line 488, in _call_with_frames_removed
  File "/opt/airflow/dags/my_first_dag.py", line 9, in <module>
    with DAG(dag_id  = 'my_first_dag',
         ^^^^^^^^^^^^^^^^^^^^^^^^^^^^^
TypeError: DAG.__init__() got an unexpected keyword argument 'scheduler_interval'
[2024-05-10T15:53:19.740+0000] {processor.py:842} WARNING - No viable dags retrieved from /opt/airflow/dags/my_first_dag.py
[2024-05-10T15:53:19.787+0000] {processor.py:183} INFO - Processing /opt/airflow/dags/my_first_dag.py took 0.101 seconds
[2024-05-10T15:53:50.033+0000] {processor.py:161} INFO - Started process (PID=259) to work on /opt/airflow/dags/my_first_dag.py
[2024-05-10T15:53:50.035+0000] {processor.py:830} INFO - Processing file /opt/airflow/dags/my_first_dag.py for tasks to queue
[2024-05-10T15:53:50.039+0000] {logging_mixin.py:188} INFO - [2024-05-10T15:53:50.038+0000] {dagbag.py:545} INFO - Filling up the DagBag from /opt/airflow/dags/my_first_dag.py
[2024-05-10T15:53:50.047+0000] {logging_mixin.py:188} INFO - [2024-05-10T15:53:50.045+0000] {dagbag.py:355} ERROR - Failed to import: /opt/airflow/dags/my_first_dag.py
Traceback (most recent call last):
  File "/home/airflow/.local/lib/python3.12/site-packages/airflow/models/dagbag.py", line 351, in parse
    loader.exec_module(new_module)
  File "<frozen importlib._bootstrap_external>", line 995, in exec_module
  File "<frozen importlib._bootstrap>", line 488, in _call_with_frames_removed
  File "/opt/airflow/dags/my_first_dag.py", line 9, in <module>
    with DAG(dag_id  = 'my_first_dag',
         ^^^^^^^^^^^^^^^^^^^^^^^^^^^^^
TypeError: DAG.__init__() got an unexpected keyword argument 'scheduler_interval'
[2024-05-10T15:53:50.048+0000] {processor.py:842} WARNING - No viable dags retrieved from /opt/airflow/dags/my_first_dag.py
[2024-05-10T15:53:50.076+0000] {processor.py:183} INFO - Processing /opt/airflow/dags/my_first_dag.py took 0.053 seconds
[2024-05-10T15:54:21.410+0000] {processor.py:161} INFO - Started process (PID=270) to work on /opt/airflow/dags/my_first_dag.py
[2024-05-10T15:54:21.560+0000] {processor.py:830} INFO - Processing file /opt/airflow/dags/my_first_dag.py for tasks to queue
[2024-05-10T15:54:21.740+0000] {logging_mixin.py:188} INFO - [2024-05-10T15:54:21.725+0000] {dagbag.py:545} INFO - Filling up the DagBag from /opt/airflow/dags/my_first_dag.py
[2024-05-10T15:54:21.898+0000] {logging_mixin.py:188} INFO - [2024-05-10T15:54:21.862+0000] {dagbag.py:355} ERROR - Failed to import: /opt/airflow/dags/my_first_dag.py
Traceback (most recent call last):
  File "/home/airflow/.local/lib/python3.12/site-packages/airflow/models/dagbag.py", line 351, in parse
    loader.exec_module(new_module)
  File "<frozen importlib._bootstrap_external>", line 995, in exec_module
  File "<frozen importlib._bootstrap>", line 488, in _call_with_frames_removed
  File "/opt/airflow/dags/my_first_dag.py", line 9, in <module>
    with DAG(dag_id  = 'my_first_dag',
         ^^^^^^^^^^^^^^^^^^^^^^^^^^^^^
TypeError: DAG.__init__() got an unexpected keyword argument 'scheduler_interval'
[2024-05-10T15:54:21.902+0000] {processor.py:842} WARNING - No viable dags retrieved from /opt/airflow/dags/my_first_dag.py
[2024-05-10T15:54:22.700+0000] {processor.py:183} INFO - Processing /opt/airflow/dags/my_first_dag.py took 2.073 seconds
[2024-05-10T15:54:53.190+0000] {processor.py:161} INFO - Started process (PID=281) to work on /opt/airflow/dags/my_first_dag.py
[2024-05-10T15:54:53.193+0000] {processor.py:830} INFO - Processing file /opt/airflow/dags/my_first_dag.py for tasks to queue
[2024-05-10T15:54:53.201+0000] {logging_mixin.py:188} INFO - [2024-05-10T15:54:53.199+0000] {dagbag.py:545} INFO - Filling up the DagBag from /opt/airflow/dags/my_first_dag.py
[2024-05-10T15:54:53.220+0000] {logging_mixin.py:188} INFO - [2024-05-10T15:54:53.216+0000] {dagbag.py:355} ERROR - Failed to import: /opt/airflow/dags/my_first_dag.py
Traceback (most recent call last):
  File "/home/airflow/.local/lib/python3.12/site-packages/airflow/models/dagbag.py", line 351, in parse
    loader.exec_module(new_module)
  File "<frozen importlib._bootstrap_external>", line 995, in exec_module
  File "<frozen importlib._bootstrap>", line 488, in _call_with_frames_removed
  File "/opt/airflow/dags/my_first_dag.py", line 9, in <module>
    with DAG(dag_id  = 'my_first_dag',
         ^^^^^^^^^^^^^^^^^^^^^^^^^^^^^
TypeError: DAG.__init__() got an unexpected keyword argument 'scheduler_interval'
[2024-05-10T15:54:53.222+0000] {processor.py:842} WARNING - No viable dags retrieved from /opt/airflow/dags/my_first_dag.py
[2024-05-10T15:54:53.259+0000] {processor.py:183} INFO - Processing /opt/airflow/dags/my_first_dag.py took 0.090 seconds
[2024-05-10T15:55:23.707+0000] {processor.py:161} INFO - Started process (PID=292) to work on /opt/airflow/dags/my_first_dag.py
[2024-05-10T15:55:23.708+0000] {processor.py:830} INFO - Processing file /opt/airflow/dags/my_first_dag.py for tasks to queue
[2024-05-10T15:55:23.712+0000] {logging_mixin.py:188} INFO - [2024-05-10T15:55:23.711+0000] {dagbag.py:545} INFO - Filling up the DagBag from /opt/airflow/dags/my_first_dag.py
[2024-05-10T15:55:23.722+0000] {logging_mixin.py:188} INFO - [2024-05-10T15:55:23.719+0000] {dagbag.py:355} ERROR - Failed to import: /opt/airflow/dags/my_first_dag.py
Traceback (most recent call last):
  File "/home/airflow/.local/lib/python3.12/site-packages/airflow/models/dagbag.py", line 351, in parse
    loader.exec_module(new_module)
  File "<frozen importlib._bootstrap_external>", line 995, in exec_module
  File "<frozen importlib._bootstrap>", line 488, in _call_with_frames_removed
  File "/opt/airflow/dags/my_first_dag.py", line 9, in <module>
    with DAG(dag_id  = 'my_first_dag',
         ^^^^^^^^^^^^^^^^^^^^^^^^^^^^^
TypeError: DAG.__init__() got an unexpected keyword argument 'scheduler_interval'
[2024-05-10T15:55:23.723+0000] {processor.py:842} WARNING - No viable dags retrieved from /opt/airflow/dags/my_first_dag.py
[2024-05-10T15:55:23.751+0000] {processor.py:183} INFO - Processing /opt/airflow/dags/my_first_dag.py took 0.052 seconds
[2024-05-10T15:55:54.138+0000] {processor.py:161} INFO - Started process (PID=302) to work on /opt/airflow/dags/my_first_dag.py
[2024-05-10T15:55:54.140+0000] {processor.py:830} INFO - Processing file /opt/airflow/dags/my_first_dag.py for tasks to queue
[2024-05-10T15:55:54.143+0000] {logging_mixin.py:188} INFO - [2024-05-10T15:55:54.143+0000] {dagbag.py:545} INFO - Filling up the DagBag from /opt/airflow/dags/my_first_dag.py
[2024-05-10T15:55:54.151+0000] {logging_mixin.py:188} INFO - [2024-05-10T15:55:54.149+0000] {dagbag.py:355} ERROR - Failed to import: /opt/airflow/dags/my_first_dag.py
Traceback (most recent call last):
  File "/home/airflow/.local/lib/python3.12/site-packages/airflow/models/dagbag.py", line 351, in parse
    loader.exec_module(new_module)
  File "<frozen importlib._bootstrap_external>", line 995, in exec_module
  File "<frozen importlib._bootstrap>", line 488, in _call_with_frames_removed
  File "/opt/airflow/dags/my_first_dag.py", line 9, in <module>
    with DAG(dag_id  = 'my_first_dag',
         ^^^^^^^^^^^^^^^^^^^^^^^^^^^^^
TypeError: DAG.__init__() got an unexpected keyword argument 'scheduler_interval'
[2024-05-10T15:55:54.152+0000] {processor.py:842} WARNING - No viable dags retrieved from /opt/airflow/dags/my_first_dag.py
[2024-05-10T15:55:54.209+0000] {processor.py:183} INFO - Processing /opt/airflow/dags/my_first_dag.py took 0.079 seconds
[2024-05-10T15:56:24.505+0000] {processor.py:161} INFO - Started process (PID=312) to work on /opt/airflow/dags/my_first_dag.py
[2024-05-10T15:56:24.507+0000] {processor.py:830} INFO - Processing file /opt/airflow/dags/my_first_dag.py for tasks to queue
[2024-05-10T15:56:24.510+0000] {logging_mixin.py:188} INFO - [2024-05-10T15:56:24.509+0000] {dagbag.py:545} INFO - Filling up the DagBag from /opt/airflow/dags/my_first_dag.py
[2024-05-10T15:56:24.522+0000] {logging_mixin.py:188} INFO - [2024-05-10T15:56:24.519+0000] {dagbag.py:355} ERROR - Failed to import: /opt/airflow/dags/my_first_dag.py
Traceback (most recent call last):
  File "/home/airflow/.local/lib/python3.12/site-packages/airflow/models/dagbag.py", line 351, in parse
    loader.exec_module(new_module)
  File "<frozen importlib._bootstrap_external>", line 995, in exec_module
  File "<frozen importlib._bootstrap>", line 488, in _call_with_frames_removed
  File "/opt/airflow/dags/my_first_dag.py", line 9, in <module>
    with DAG(dag_id  = 'my_first_dag',
         ^^^^^^^^^^^^^^^^^^^^^^^^^^^^^
TypeError: DAG.__init__() got an unexpected keyword argument 'scheduler_interval'
[2024-05-10T15:56:24.523+0000] {processor.py:842} WARNING - No viable dags retrieved from /opt/airflow/dags/my_first_dag.py
[2024-05-10T15:56:24.558+0000] {processor.py:183} INFO - Processing /opt/airflow/dags/my_first_dag.py took 0.063 seconds
[2024-05-10T15:56:54.752+0000] {processor.py:161} INFO - Started process (PID=323) to work on /opt/airflow/dags/my_first_dag.py
[2024-05-10T15:56:54.753+0000] {processor.py:830} INFO - Processing file /opt/airflow/dags/my_first_dag.py for tasks to queue
[2024-05-10T15:56:54.756+0000] {logging_mixin.py:188} INFO - [2024-05-10T15:56:54.756+0000] {dagbag.py:545} INFO - Filling up the DagBag from /opt/airflow/dags/my_first_dag.py
[2024-05-10T15:56:54.766+0000] {logging_mixin.py:188} INFO - [2024-05-10T15:56:54.763+0000] {dagbag.py:355} ERROR - Failed to import: /opt/airflow/dags/my_first_dag.py
Traceback (most recent call last):
  File "/home/airflow/.local/lib/python3.12/site-packages/airflow/models/dagbag.py", line 351, in parse
    loader.exec_module(new_module)
  File "<frozen importlib._bootstrap_external>", line 995, in exec_module
  File "<frozen importlib._bootstrap>", line 488, in _call_with_frames_removed
  File "/opt/airflow/dags/my_first_dag.py", line 9, in <module>
    with DAG(dag_id  = 'my_first_dag',
         ^^^^^^^^^^^^^^^^^^^^^^^^^^^^^
TypeError: DAG.__init__() got an unexpected keyword argument 'scheduler_interval'
[2024-05-10T15:56:54.768+0000] {processor.py:842} WARNING - No viable dags retrieved from /opt/airflow/dags/my_first_dag.py
[2024-05-10T15:56:54.794+0000] {processor.py:183} INFO - Processing /opt/airflow/dags/my_first_dag.py took 0.050 seconds
[2024-05-10T15:57:25.126+0000] {processor.py:161} INFO - Started process (PID=334) to work on /opt/airflow/dags/my_first_dag.py
[2024-05-10T15:57:25.127+0000] {processor.py:830} INFO - Processing file /opt/airflow/dags/my_first_dag.py for tasks to queue
[2024-05-10T15:57:25.130+0000] {logging_mixin.py:188} INFO - [2024-05-10T15:57:25.130+0000] {dagbag.py:545} INFO - Filling up the DagBag from /opt/airflow/dags/my_first_dag.py
[2024-05-10T15:57:25.138+0000] {logging_mixin.py:188} INFO - [2024-05-10T15:57:25.136+0000] {dagbag.py:355} ERROR - Failed to import: /opt/airflow/dags/my_first_dag.py
Traceback (most recent call last):
  File "/home/airflow/.local/lib/python3.12/site-packages/airflow/models/dagbag.py", line 351, in parse
    loader.exec_module(new_module)
  File "<frozen importlib._bootstrap_external>", line 995, in exec_module
  File "<frozen importlib._bootstrap>", line 488, in _call_with_frames_removed
  File "/opt/airflow/dags/my_first_dag.py", line 9, in <module>
    with DAG(dag_id  = 'my_first_dag',
         ^^^^^^^^^^^^^^^^^^^^^^^^^^^^^
TypeError: DAG.__init__() got an unexpected keyword argument 'scheduler_interval'
[2024-05-10T15:57:25.139+0000] {processor.py:842} WARNING - No viable dags retrieved from /opt/airflow/dags/my_first_dag.py
[2024-05-10T15:57:25.169+0000] {processor.py:183} INFO - Processing /opt/airflow/dags/my_first_dag.py took 0.051 seconds
[2024-05-10T15:57:43.366+0000] {processor.py:161} INFO - Started process (PID=345) to work on /opt/airflow/dags/my_first_dag.py
[2024-05-10T15:57:43.372+0000] {processor.py:830} INFO - Processing file /opt/airflow/dags/my_first_dag.py for tasks to queue
[2024-05-10T15:57:43.376+0000] {logging_mixin.py:188} INFO - [2024-05-10T15:57:43.375+0000] {dagbag.py:545} INFO - Filling up the DagBag from /opt/airflow/dags/my_first_dag.py
[2024-05-10T15:57:43.390+0000] {logging_mixin.py:188} INFO - [2024-05-10T15:57:43.388+0000] {dagbag.py:355} ERROR - Failed to import: /opt/airflow/dags/my_first_dag.py
Traceback (most recent call last):
  File "/home/airflow/.local/lib/python3.12/site-packages/airflow/models/dagbag.py", line 351, in parse
    loader.exec_module(new_module)
  File "<frozen importlib._bootstrap_external>", line 995, in exec_module
  File "<frozen importlib._bootstrap>", line 488, in _call_with_frames_removed
  File "/opt/airflow/dags/my_first_dag.py", line 9, in <module>
    with DAG(dag_id  = 'my_first_dag',
         ^^^^^^^^^^^^^^^^^^^^^^^^^^^^^
TypeError: DAG.__init__() got an unexpected keyword argument 'scheduler_interval'
[2024-05-10T15:57:43.391+0000] {processor.py:842} WARNING - No viable dags retrieved from /opt/airflow/dags/my_first_dag.py
[2024-05-10T15:57:43.431+0000] {processor.py:183} INFO - Processing /opt/airflow/dags/my_first_dag.py took 0.082 seconds
[2024-05-10T15:58:13.568+0000] {processor.py:161} INFO - Started process (PID=356) to work on /opt/airflow/dags/my_first_dag.py
[2024-05-10T15:58:13.570+0000] {processor.py:830} INFO - Processing file /opt/airflow/dags/my_first_dag.py for tasks to queue
[2024-05-10T15:58:13.574+0000] {logging_mixin.py:188} INFO - [2024-05-10T15:58:13.573+0000] {dagbag.py:545} INFO - Filling up the DagBag from /opt/airflow/dags/my_first_dag.py
[2024-05-10T15:58:13.583+0000] {logging_mixin.py:188} INFO - [2024-05-10T15:58:13.581+0000] {dagbag.py:355} ERROR - Failed to import: /opt/airflow/dags/my_first_dag.py
Traceback (most recent call last):
  File "/home/airflow/.local/lib/python3.12/site-packages/airflow/models/dagbag.py", line 351, in parse
    loader.exec_module(new_module)
  File "<frozen importlib._bootstrap_external>", line 995, in exec_module
  File "<frozen importlib._bootstrap>", line 488, in _call_with_frames_removed
  File "/opt/airflow/dags/my_first_dag.py", line 9, in <module>
    with DAG(dag_id  = 'my_first_dag',
         ^^^^^^^^^^^^^^^^^^^^^^^^^^^^^
TypeError: DAG.__init__() got an unexpected keyword argument 'scheduler_interval'
[2024-05-10T15:58:13.585+0000] {processor.py:842} WARNING - No viable dags retrieved from /opt/airflow/dags/my_first_dag.py
[2024-05-10T15:58:13.626+0000] {processor.py:183} INFO - Processing /opt/airflow/dags/my_first_dag.py took 0.067 seconds
[2024-05-10T15:58:43.792+0000] {processor.py:161} INFO - Started process (PID=367) to work on /opt/airflow/dags/my_first_dag.py
[2024-05-10T15:58:43.794+0000] {processor.py:830} INFO - Processing file /opt/airflow/dags/my_first_dag.py for tasks to queue
[2024-05-10T15:58:43.796+0000] {logging_mixin.py:188} INFO - [2024-05-10T15:58:43.796+0000] {dagbag.py:545} INFO - Filling up the DagBag from /opt/airflow/dags/my_first_dag.py
[2024-05-10T15:58:43.806+0000] {logging_mixin.py:188} INFO - [2024-05-10T15:58:43.803+0000] {dagbag.py:355} ERROR - Failed to import: /opt/airflow/dags/my_first_dag.py
Traceback (most recent call last):
  File "/home/airflow/.local/lib/python3.12/site-packages/airflow/models/dagbag.py", line 351, in parse
    loader.exec_module(new_module)
  File "<frozen importlib._bootstrap_external>", line 995, in exec_module
  File "<frozen importlib._bootstrap>", line 488, in _call_with_frames_removed
  File "/opt/airflow/dags/my_first_dag.py", line 9, in <module>
    with DAG(dag_id  = 'my_first_dag',
         ^^^^^^^^^^^^^^^^^^^^^^^^^^^^^
TypeError: DAG.__init__() got an unexpected keyword argument 'scheduler_interval'
[2024-05-10T15:58:43.807+0000] {processor.py:842} WARNING - No viable dags retrieved from /opt/airflow/dags/my_first_dag.py
[2024-05-10T15:58:43.835+0000] {processor.py:183} INFO - Processing /opt/airflow/dags/my_first_dag.py took 0.053 seconds
[2024-05-10T15:59:14.027+0000] {processor.py:161} INFO - Started process (PID=378) to work on /opt/airflow/dags/my_first_dag.py
[2024-05-10T15:59:14.029+0000] {processor.py:830} INFO - Processing file /opt/airflow/dags/my_first_dag.py for tasks to queue
[2024-05-10T15:59:14.032+0000] {logging_mixin.py:188} INFO - [2024-05-10T15:59:14.031+0000] {dagbag.py:545} INFO - Filling up the DagBag from /opt/airflow/dags/my_first_dag.py
[2024-05-10T15:59:14.039+0000] {logging_mixin.py:188} INFO - [2024-05-10T15:59:14.037+0000] {dagbag.py:355} ERROR - Failed to import: /opt/airflow/dags/my_first_dag.py
Traceback (most recent call last):
  File "/home/airflow/.local/lib/python3.12/site-packages/airflow/models/dagbag.py", line 351, in parse
    loader.exec_module(new_module)
  File "<frozen importlib._bootstrap_external>", line 995, in exec_module
  File "<frozen importlib._bootstrap>", line 488, in _call_with_frames_removed
  File "/opt/airflow/dags/my_first_dag.py", line 9, in <module>
    with DAG(dag_id  = 'my_first_dag',
         ^^^^^^^^^^^^^^^^^^^^^^^^^^^^^
TypeError: DAG.__init__() got an unexpected keyword argument 'scheduler_interval'
[2024-05-10T15:59:14.041+0000] {processor.py:842} WARNING - No viable dags retrieved from /opt/airflow/dags/my_first_dag.py
[2024-05-10T15:59:14.076+0000] {processor.py:183} INFO - Processing /opt/airflow/dags/my_first_dag.py took 0.057 seconds
[2024-05-10T15:59:44.407+0000] {processor.py:161} INFO - Started process (PID=389) to work on /opt/airflow/dags/my_first_dag.py
[2024-05-10T15:59:44.410+0000] {processor.py:830} INFO - Processing file /opt/airflow/dags/my_first_dag.py for tasks to queue
[2024-05-10T15:59:44.413+0000] {logging_mixin.py:188} INFO - [2024-05-10T15:59:44.412+0000] {dagbag.py:545} INFO - Filling up the DagBag from /opt/airflow/dags/my_first_dag.py
[2024-05-10T15:59:44.422+0000] {logging_mixin.py:188} INFO - [2024-05-10T15:59:44.419+0000] {dagbag.py:355} ERROR - Failed to import: /opt/airflow/dags/my_first_dag.py
Traceback (most recent call last):
  File "/home/airflow/.local/lib/python3.12/site-packages/airflow/models/dagbag.py", line 351, in parse
    loader.exec_module(new_module)
  File "<frozen importlib._bootstrap_external>", line 995, in exec_module
  File "<frozen importlib._bootstrap>", line 488, in _call_with_frames_removed
  File "/opt/airflow/dags/my_first_dag.py", line 9, in <module>
    with DAG(dag_id  = 'my_first_dag',
         ^^^^^^^^^^^^^^^^^^^^^^^^^^^^^
TypeError: DAG.__init__() got an unexpected keyword argument 'scheduler_interval'
[2024-05-10T15:59:44.423+0000] {processor.py:842} WARNING - No viable dags retrieved from /opt/airflow/dags/my_first_dag.py
[2024-05-10T15:59:44.455+0000] {processor.py:183} INFO - Processing /opt/airflow/dags/my_first_dag.py took 0.057 seconds
[2024-05-10T16:00:14.708+0000] {processor.py:161} INFO - Started process (PID=400) to work on /opt/airflow/dags/my_first_dag.py
[2024-05-10T16:00:14.710+0000] {processor.py:830} INFO - Processing file /opt/airflow/dags/my_first_dag.py for tasks to queue
[2024-05-10T16:00:14.713+0000] {logging_mixin.py:188} INFO - [2024-05-10T16:00:14.713+0000] {dagbag.py:545} INFO - Filling up the DagBag from /opt/airflow/dags/my_first_dag.py
[2024-05-10T16:00:14.720+0000] {logging_mixin.py:188} INFO - [2024-05-10T16:00:14.718+0000] {dagbag.py:355} ERROR - Failed to import: /opt/airflow/dags/my_first_dag.py
Traceback (most recent call last):
  File "/home/airflow/.local/lib/python3.12/site-packages/airflow/models/dagbag.py", line 351, in parse
    loader.exec_module(new_module)
  File "<frozen importlib._bootstrap_external>", line 995, in exec_module
  File "<frozen importlib._bootstrap>", line 488, in _call_with_frames_removed
  File "/opt/airflow/dags/my_first_dag.py", line 9, in <module>
    with DAG(dag_id  = 'my_first_dag',
         ^^^^^^^^^^^^^^^^^^^^^^^^^^^^^
TypeError: DAG.__init__() got an unexpected keyword argument 'scheduler_interval'
[2024-05-10T16:00:14.721+0000] {processor.py:842} WARNING - No viable dags retrieved from /opt/airflow/dags/my_first_dag.py
[2024-05-10T16:00:14.750+0000] {processor.py:183} INFO - Processing /opt/airflow/dags/my_first_dag.py took 0.050 seconds
[2024-05-10T16:00:44.999+0000] {processor.py:161} INFO - Started process (PID=411) to work on /opt/airflow/dags/my_first_dag.py
[2024-05-10T16:00:45.005+0000] {processor.py:830} INFO - Processing file /opt/airflow/dags/my_first_dag.py for tasks to queue
[2024-05-10T16:00:45.009+0000] {logging_mixin.py:188} INFO - [2024-05-10T16:00:45.009+0000] {dagbag.py:545} INFO - Filling up the DagBag from /opt/airflow/dags/my_first_dag.py
[2024-05-10T16:00:45.035+0000] {logging_mixin.py:188} INFO - [2024-05-10T16:00:45.025+0000] {dagbag.py:355} ERROR - Failed to import: /opt/airflow/dags/my_first_dag.py
Traceback (most recent call last):
  File "/home/airflow/.local/lib/python3.12/site-packages/airflow/models/dagbag.py", line 351, in parse
    loader.exec_module(new_module)
  File "<frozen importlib._bootstrap_external>", line 995, in exec_module
  File "<frozen importlib._bootstrap>", line 488, in _call_with_frames_removed
  File "/opt/airflow/dags/my_first_dag.py", line 9, in <module>
    with DAG(dag_id  = 'my_first_dag',
         ^^^^^^^^^^^^^^^^^^^^^^^^^^^^^
TypeError: DAG.__init__() got an unexpected keyword argument 'scheduler_interval'
[2024-05-10T16:00:45.039+0000] {processor.py:842} WARNING - No viable dags retrieved from /opt/airflow/dags/my_first_dag.py
[2024-05-10T16:00:45.088+0000] {processor.py:183} INFO - Processing /opt/airflow/dags/my_first_dag.py took 0.102 seconds
[2024-05-10T16:01:15.561+0000] {processor.py:161} INFO - Started process (PID=421) to work on /opt/airflow/dags/my_first_dag.py
[2024-05-10T16:01:15.563+0000] {processor.py:830} INFO - Processing file /opt/airflow/dags/my_first_dag.py for tasks to queue
[2024-05-10T16:01:15.568+0000] {logging_mixin.py:188} INFO - [2024-05-10T16:01:15.567+0000] {dagbag.py:545} INFO - Filling up the DagBag from /opt/airflow/dags/my_first_dag.py
[2024-05-10T16:01:15.576+0000] {logging_mixin.py:188} INFO - [2024-05-10T16:01:15.574+0000] {dagbag.py:355} ERROR - Failed to import: /opt/airflow/dags/my_first_dag.py
Traceback (most recent call last):
  File "/home/airflow/.local/lib/python3.12/site-packages/airflow/models/dagbag.py", line 351, in parse
    loader.exec_module(new_module)
  File "<frozen importlib._bootstrap_external>", line 995, in exec_module
  File "<frozen importlib._bootstrap>", line 488, in _call_with_frames_removed
  File "/opt/airflow/dags/my_first_dag.py", line 9, in <module>
    with DAG(dag_id  = 'my_first_dag',
         ^^^^^^^^^^^^^^^^^^^^^^^^^^^^^
TypeError: DAG.__init__() got an unexpected keyword argument 'scheduler_interval'
[2024-05-10T16:01:15.578+0000] {processor.py:842} WARNING - No viable dags retrieved from /opt/airflow/dags/my_first_dag.py
[2024-05-10T16:01:15.604+0000] {processor.py:183} INFO - Processing /opt/airflow/dags/my_first_dag.py took 0.059 seconds
[2024-05-10T16:01:46.165+0000] {processor.py:161} INFO - Started process (PID=432) to work on /opt/airflow/dags/my_first_dag.py
[2024-05-10T16:01:46.168+0000] {processor.py:830} INFO - Processing file /opt/airflow/dags/my_first_dag.py for tasks to queue
[2024-05-10T16:01:46.175+0000] {logging_mixin.py:188} INFO - [2024-05-10T16:01:46.174+0000] {dagbag.py:545} INFO - Filling up the DagBag from /opt/airflow/dags/my_first_dag.py
[2024-05-10T16:01:46.185+0000] {logging_mixin.py:188} INFO - [2024-05-10T16:01:46.182+0000] {dagbag.py:355} ERROR - Failed to import: /opt/airflow/dags/my_first_dag.py
Traceback (most recent call last):
  File "/home/airflow/.local/lib/python3.12/site-packages/airflow/models/dagbag.py", line 351, in parse
    loader.exec_module(new_module)
  File "<frozen importlib._bootstrap_external>", line 995, in exec_module
  File "<frozen importlib._bootstrap>", line 488, in _call_with_frames_removed
  File "/opt/airflow/dags/my_first_dag.py", line 9, in <module>
    with DAG(dag_id  = 'my_first_dag',
         ^^^^^^^^^^^^^^^^^^^^^^^^^^^^^
TypeError: DAG.__init__() got an unexpected keyword argument 'scheduler_interval'
[2024-05-10T16:01:46.186+0000] {processor.py:842} WARNING - No viable dags retrieved from /opt/airflow/dags/my_first_dag.py
[2024-05-10T16:01:46.221+0000] {processor.py:183} INFO - Processing /opt/airflow/dags/my_first_dag.py took 0.081 seconds
[2024-05-10T16:02:16.495+0000] {processor.py:161} INFO - Started process (PID=442) to work on /opt/airflow/dags/my_first_dag.py
[2024-05-10T16:02:16.497+0000] {processor.py:830} INFO - Processing file /opt/airflow/dags/my_first_dag.py for tasks to queue
[2024-05-10T16:02:16.505+0000] {logging_mixin.py:188} INFO - [2024-05-10T16:02:16.503+0000] {dagbag.py:545} INFO - Filling up the DagBag from /opt/airflow/dags/my_first_dag.py
[2024-05-10T16:02:16.541+0000] {logging_mixin.py:188} INFO - [2024-05-10T16:02:16.539+0000] {dagbag.py:355} ERROR - Failed to import: /opt/airflow/dags/my_first_dag.py
Traceback (most recent call last):
  File "/home/airflow/.local/lib/python3.12/site-packages/airflow/models/dagbag.py", line 351, in parse
    loader.exec_module(new_module)
  File "<frozen importlib._bootstrap_external>", line 995, in exec_module
  File "<frozen importlib._bootstrap>", line 488, in _call_with_frames_removed
  File "/opt/airflow/dags/my_first_dag.py", line 9, in <module>
    with DAG(dag_id  = 'my_first_dag',
         ^^^^^^^^^^^^^^^^^^^^^^^^^^^^^
TypeError: DAG.__init__() got an unexpected keyword argument 'scheduler_interval'
[2024-05-10T16:02:16.543+0000] {processor.py:842} WARNING - No viable dags retrieved from /opt/airflow/dags/my_first_dag.py
[2024-05-10T16:02:16.579+0000] {processor.py:183} INFO - Processing /opt/airflow/dags/my_first_dag.py took 0.098 seconds
[2024-05-10T16:02:46.825+0000] {processor.py:161} INFO - Started process (PID=453) to work on /opt/airflow/dags/my_first_dag.py
[2024-05-10T16:02:46.829+0000] {processor.py:830} INFO - Processing file /opt/airflow/dags/my_first_dag.py for tasks to queue
[2024-05-10T16:02:46.840+0000] {logging_mixin.py:188} INFO - [2024-05-10T16:02:46.839+0000] {dagbag.py:545} INFO - Filling up the DagBag from /opt/airflow/dags/my_first_dag.py
[2024-05-10T16:02:46.866+0000] {logging_mixin.py:188} INFO - [2024-05-10T16:02:46.858+0000] {dagbag.py:355} ERROR - Failed to import: /opt/airflow/dags/my_first_dag.py
Traceback (most recent call last):
  File "/home/airflow/.local/lib/python3.12/site-packages/airflow/models/dagbag.py", line 351, in parse
    loader.exec_module(new_module)
  File "<frozen importlib._bootstrap_external>", line 995, in exec_module
  File "<frozen importlib._bootstrap>", line 488, in _call_with_frames_removed
  File "/opt/airflow/dags/my_first_dag.py", line 9, in <module>
    with DAG(dag_id  = 'my_first_dag',
         ^^^^^^^^^^^^^^^^^^^^^^^^^^^^^
TypeError: DAG.__init__() got an unexpected keyword argument 'scheduler_interval'
[2024-05-10T16:02:46.870+0000] {processor.py:842} WARNING - No viable dags retrieved from /opt/airflow/dags/my_first_dag.py
[2024-05-10T16:02:46.911+0000] {processor.py:183} INFO - Processing /opt/airflow/dags/my_first_dag.py took 0.094 seconds
[2024-05-10T16:03:17.285+0000] {processor.py:161} INFO - Started process (PID=464) to work on /opt/airflow/dags/my_first_dag.py
[2024-05-10T16:03:17.288+0000] {processor.py:830} INFO - Processing file /opt/airflow/dags/my_first_dag.py for tasks to queue
[2024-05-10T16:03:17.672+0000] {logging_mixin.py:188} INFO - [2024-05-10T16:03:17.304+0000] {dagbag.py:545} INFO - Filling up the DagBag from /opt/airflow/dags/my_first_dag.py
[2024-05-10T16:03:17.724+0000] {logging_mixin.py:188} INFO - [2024-05-10T16:03:17.708+0000] {dagbag.py:355} ERROR - Failed to import: /opt/airflow/dags/my_first_dag.py
Traceback (most recent call last):
  File "/home/airflow/.local/lib/python3.12/site-packages/airflow/models/dagbag.py", line 351, in parse
    loader.exec_module(new_module)
  File "<frozen importlib._bootstrap_external>", line 995, in exec_module
  File "<frozen importlib._bootstrap>", line 488, in _call_with_frames_removed
  File "/opt/airflow/dags/my_first_dag.py", line 9, in <module>
    with DAG(dag_id  = 'my_first_dag',
         ^^^^^^^^^^^^^^^^^^^^^^^^^^^^^
TypeError: DAG.__init__() got an unexpected keyword argument 'scheduler_interval'
[2024-05-10T16:03:17.725+0000] {processor.py:842} WARNING - No viable dags retrieved from /opt/airflow/dags/my_first_dag.py
[2024-05-10T16:03:17.868+0000] {processor.py:183} INFO - Processing /opt/airflow/dags/my_first_dag.py took 0.601 seconds
[2024-05-10T16:03:48.059+0000] {processor.py:161} INFO - Started process (PID=474) to work on /opt/airflow/dags/my_first_dag.py
[2024-05-10T16:03:48.061+0000] {processor.py:830} INFO - Processing file /opt/airflow/dags/my_first_dag.py for tasks to queue
[2024-05-10T16:03:48.067+0000] {logging_mixin.py:188} INFO - [2024-05-10T16:03:48.066+0000] {dagbag.py:545} INFO - Filling up the DagBag from /opt/airflow/dags/my_first_dag.py
[2024-05-10T16:03:48.077+0000] {logging_mixin.py:188} INFO - [2024-05-10T16:03:48.075+0000] {dagbag.py:355} ERROR - Failed to import: /opt/airflow/dags/my_first_dag.py
Traceback (most recent call last):
  File "/home/airflow/.local/lib/python3.12/site-packages/airflow/models/dagbag.py", line 351, in parse
    loader.exec_module(new_module)
  File "<frozen importlib._bootstrap_external>", line 995, in exec_module
  File "<frozen importlib._bootstrap>", line 488, in _call_with_frames_removed
  File "/opt/airflow/dags/my_first_dag.py", line 9, in <module>
    with DAG(dag_id  = 'my_first_dag',
         ^^^^^^^^^^^^^^^^^^^^^^^^^^^^^
TypeError: DAG.__init__() got an unexpected keyword argument 'scheduler_interval'
[2024-05-10T16:03:48.079+0000] {processor.py:842} WARNING - No viable dags retrieved from /opt/airflow/dags/my_first_dag.py
[2024-05-10T16:03:48.117+0000] {processor.py:183} INFO - Processing /opt/airflow/dags/my_first_dag.py took 0.075 seconds
[2024-05-10T16:04:18.405+0000] {processor.py:161} INFO - Started process (PID=485) to work on /opt/airflow/dags/my_first_dag.py
[2024-05-10T16:04:18.406+0000] {processor.py:830} INFO - Processing file /opt/airflow/dags/my_first_dag.py for tasks to queue
[2024-05-10T16:04:18.410+0000] {logging_mixin.py:188} INFO - [2024-05-10T16:04:18.410+0000] {dagbag.py:545} INFO - Filling up the DagBag from /opt/airflow/dags/my_first_dag.py
[2024-05-10T16:04:18.417+0000] {logging_mixin.py:188} INFO - [2024-05-10T16:04:18.415+0000] {dagbag.py:355} ERROR - Failed to import: /opt/airflow/dags/my_first_dag.py
Traceback (most recent call last):
  File "/home/airflow/.local/lib/python3.12/site-packages/airflow/models/dagbag.py", line 351, in parse
    loader.exec_module(new_module)
  File "<frozen importlib._bootstrap_external>", line 995, in exec_module
  File "<frozen importlib._bootstrap>", line 488, in _call_with_frames_removed
  File "/opt/airflow/dags/my_first_dag.py", line 9, in <module>
    with DAG(dag_id  = 'my_first_dag',
         ^^^^^^^^^^^^^^^^^^^^^^^^^^^^^
TypeError: DAG.__init__() got an unexpected keyword argument 'scheduler_interval'
[2024-05-10T16:04:18.419+0000] {processor.py:842} WARNING - No viable dags retrieved from /opt/airflow/dags/my_first_dag.py
[2024-05-10T16:04:18.447+0000] {processor.py:183} INFO - Processing /opt/airflow/dags/my_first_dag.py took 0.051 seconds
[2024-05-10T16:04:48.715+0000] {processor.py:161} INFO - Started process (PID=497) to work on /opt/airflow/dags/my_first_dag.py
[2024-05-10T16:04:48.717+0000] {processor.py:830} INFO - Processing file /opt/airflow/dags/my_first_dag.py for tasks to queue
[2024-05-10T16:04:48.721+0000] {logging_mixin.py:188} INFO - [2024-05-10T16:04:48.720+0000] {dagbag.py:545} INFO - Filling up the DagBag from /opt/airflow/dags/my_first_dag.py
[2024-05-10T16:04:48.730+0000] {logging_mixin.py:188} INFO - [2024-05-10T16:04:48.728+0000] {dagbag.py:355} ERROR - Failed to import: /opt/airflow/dags/my_first_dag.py
Traceback (most recent call last):
  File "/home/airflow/.local/lib/python3.12/site-packages/airflow/models/dagbag.py", line 351, in parse
    loader.exec_module(new_module)
  File "<frozen importlib._bootstrap_external>", line 995, in exec_module
  File "<frozen importlib._bootstrap>", line 488, in _call_with_frames_removed
  File "/opt/airflow/dags/my_first_dag.py", line 9, in <module>
    with DAG(dag_id  = 'my_first_dag',
         ^^^^^^^^^^^^^^^^^^^^^^^^^^^^^
TypeError: DAG.__init__() got an unexpected keyword argument 'scheduler_interval'
[2024-05-10T16:04:48.732+0000] {processor.py:842} WARNING - No viable dags retrieved from /opt/airflow/dags/my_first_dag.py
[2024-05-10T16:04:48.764+0000] {processor.py:183} INFO - Processing /opt/airflow/dags/my_first_dag.py took 0.057 seconds
[2024-05-10T16:05:19.009+0000] {processor.py:161} INFO - Started process (PID=508) to work on /opt/airflow/dags/my_first_dag.py
[2024-05-10T16:05:19.010+0000] {processor.py:830} INFO - Processing file /opt/airflow/dags/my_first_dag.py for tasks to queue
[2024-05-10T16:05:19.014+0000] {logging_mixin.py:188} INFO - [2024-05-10T16:05:19.013+0000] {dagbag.py:545} INFO - Filling up the DagBag from /opt/airflow/dags/my_first_dag.py
[2024-05-10T16:05:19.020+0000] {logging_mixin.py:188} INFO - [2024-05-10T16:05:19.018+0000] {dagbag.py:355} ERROR - Failed to import: /opt/airflow/dags/my_first_dag.py
Traceback (most recent call last):
  File "/home/airflow/.local/lib/python3.12/site-packages/airflow/models/dagbag.py", line 351, in parse
    loader.exec_module(new_module)
  File "<frozen importlib._bootstrap_external>", line 995, in exec_module
  File "<frozen importlib._bootstrap>", line 488, in _call_with_frames_removed
  File "/opt/airflow/dags/my_first_dag.py", line 9, in <module>
    with DAG(dag_id  = 'my_first_dag',
         ^^^^^^^^^^^^^^^^^^^^^^^^^^^^^
TypeError: DAG.__init__() got an unexpected keyword argument 'scheduler_interval'
[2024-05-10T16:05:19.021+0000] {processor.py:842} WARNING - No viable dags retrieved from /opt/airflow/dags/my_first_dag.py
[2024-05-10T16:05:19.049+0000] {processor.py:183} INFO - Processing /opt/airflow/dags/my_first_dag.py took 0.051 seconds
[2024-05-10T16:05:49.243+0000] {processor.py:161} INFO - Started process (PID=518) to work on /opt/airflow/dags/my_first_dag.py
[2024-05-10T16:05:49.244+0000] {processor.py:830} INFO - Processing file /opt/airflow/dags/my_first_dag.py for tasks to queue
[2024-05-10T16:05:49.247+0000] {logging_mixin.py:188} INFO - [2024-05-10T16:05:49.246+0000] {dagbag.py:545} INFO - Filling up the DagBag from /opt/airflow/dags/my_first_dag.py
[2024-05-10T16:05:49.255+0000] {logging_mixin.py:188} INFO - [2024-05-10T16:05:49.252+0000] {dagbag.py:355} ERROR - Failed to import: /opt/airflow/dags/my_first_dag.py
Traceback (most recent call last):
  File "/home/airflow/.local/lib/python3.12/site-packages/airflow/models/dagbag.py", line 351, in parse
    loader.exec_module(new_module)
  File "<frozen importlib._bootstrap_external>", line 995, in exec_module
  File "<frozen importlib._bootstrap>", line 488, in _call_with_frames_removed
  File "/opt/airflow/dags/my_first_dag.py", line 9, in <module>
    with DAG(dag_id  = 'my_first_dag',
         ^^^^^^^^^^^^^^^^^^^^^^^^^^^^^
TypeError: DAG.__init__() got an unexpected keyword argument 'scheduler_interval'
[2024-05-10T16:05:49.256+0000] {processor.py:842} WARNING - No viable dags retrieved from /opt/airflow/dags/my_first_dag.py
[2024-05-10T16:05:49.281+0000] {processor.py:183} INFO - Processing /opt/airflow/dags/my_first_dag.py took 0.045 seconds
[2024-05-10T16:06:19.569+0000] {processor.py:161} INFO - Started process (PID=528) to work on /opt/airflow/dags/my_first_dag.py
[2024-05-10T16:06:19.570+0000] {processor.py:830} INFO - Processing file /opt/airflow/dags/my_first_dag.py for tasks to queue
[2024-05-10T16:06:19.573+0000] {logging_mixin.py:188} INFO - [2024-05-10T16:06:19.572+0000] {dagbag.py:545} INFO - Filling up the DagBag from /opt/airflow/dags/my_first_dag.py
[2024-05-10T16:06:19.581+0000] {logging_mixin.py:188} INFO - [2024-05-10T16:06:19.579+0000] {dagbag.py:355} ERROR - Failed to import: /opt/airflow/dags/my_first_dag.py
Traceback (most recent call last):
  File "/home/airflow/.local/lib/python3.12/site-packages/airflow/models/dagbag.py", line 351, in parse
    loader.exec_module(new_module)
  File "<frozen importlib._bootstrap_external>", line 995, in exec_module
  File "<frozen importlib._bootstrap>", line 488, in _call_with_frames_removed
  File "/opt/airflow/dags/my_first_dag.py", line 9, in <module>
    with DAG(dag_id  = 'my_first_dag',
         ^^^^^^^^^^^^^^^^^^^^^^^^^^^^^
TypeError: DAG.__init__() got an unexpected keyword argument 'scheduler_interval'
[2024-05-10T16:06:19.583+0000] {processor.py:842} WARNING - No viable dags retrieved from /opt/airflow/dags/my_first_dag.py
[2024-05-10T16:06:19.618+0000] {processor.py:183} INFO - Processing /opt/airflow/dags/my_first_dag.py took 0.056 seconds
[2024-05-10T16:06:49.914+0000] {processor.py:161} INFO - Started process (PID=539) to work on /opt/airflow/dags/my_first_dag.py
[2024-05-10T16:06:49.916+0000] {processor.py:830} INFO - Processing file /opt/airflow/dags/my_first_dag.py for tasks to queue
[2024-05-10T16:06:49.925+0000] {logging_mixin.py:188} INFO - [2024-05-10T16:06:49.924+0000] {dagbag.py:545} INFO - Filling up the DagBag from /opt/airflow/dags/my_first_dag.py
[2024-05-10T16:06:49.933+0000] {logging_mixin.py:188} INFO - [2024-05-10T16:06:49.931+0000] {dagbag.py:355} ERROR - Failed to import: /opt/airflow/dags/my_first_dag.py
Traceback (most recent call last):
  File "/home/airflow/.local/lib/python3.12/site-packages/airflow/models/dagbag.py", line 351, in parse
    loader.exec_module(new_module)
  File "<frozen importlib._bootstrap_external>", line 995, in exec_module
  File "<frozen importlib._bootstrap>", line 488, in _call_with_frames_removed
  File "/opt/airflow/dags/my_first_dag.py", line 9, in <module>
    with DAG(dag_id  = 'my_first_dag',
         ^^^^^^^^^^^^^^^^^^^^^^^^^^^^^
TypeError: DAG.__init__() got an unexpected keyword argument 'scheduler_interval'
[2024-05-10T16:06:49.940+0000] {processor.py:842} WARNING - No viable dags retrieved from /opt/airflow/dags/my_first_dag.py
[2024-05-10T16:06:49.981+0000] {processor.py:183} INFO - Processing /opt/airflow/dags/my_first_dag.py took 0.078 seconds
[2024-05-10T16:07:20.387+0000] {processor.py:161} INFO - Started process (PID=550) to work on /opt/airflow/dags/my_first_dag.py
[2024-05-10T16:07:20.388+0000] {processor.py:830} INFO - Processing file /opt/airflow/dags/my_first_dag.py for tasks to queue
[2024-05-10T16:07:20.391+0000] {logging_mixin.py:188} INFO - [2024-05-10T16:07:20.390+0000] {dagbag.py:545} INFO - Filling up the DagBag from /opt/airflow/dags/my_first_dag.py
[2024-05-10T16:07:20.399+0000] {logging_mixin.py:188} INFO - [2024-05-10T16:07:20.397+0000] {dagbag.py:355} ERROR - Failed to import: /opt/airflow/dags/my_first_dag.py
Traceback (most recent call last):
  File "/home/airflow/.local/lib/python3.12/site-packages/airflow/models/dagbag.py", line 351, in parse
    loader.exec_module(new_module)
  File "<frozen importlib._bootstrap_external>", line 995, in exec_module
  File "<frozen importlib._bootstrap>", line 488, in _call_with_frames_removed
  File "/opt/airflow/dags/my_first_dag.py", line 9, in <module>
    with DAG(dag_id  = 'my_first_dag',
         ^^^^^^^^^^^^^^^^^^^^^^^^^^^^^
TypeError: DAG.__init__() got an unexpected keyword argument 'scheduler_interval'
[2024-05-10T16:07:20.401+0000] {processor.py:842} WARNING - No viable dags retrieved from /opt/airflow/dags/my_first_dag.py
[2024-05-10T16:07:20.427+0000] {processor.py:183} INFO - Processing /opt/airflow/dags/my_first_dag.py took 0.048 seconds
[2024-05-10T16:07:47.134+0000] {processor.py:161} INFO - Started process (PID=561) to work on /opt/airflow/dags/my_first_dag.py
[2024-05-10T16:07:47.179+0000] {processor.py:830} INFO - Processing file /opt/airflow/dags/my_first_dag.py for tasks to queue
[2024-05-10T16:07:47.215+0000] {logging_mixin.py:188} INFO - [2024-05-10T16:07:47.214+0000] {dagbag.py:545} INFO - Filling up the DagBag from /opt/airflow/dags/my_first_dag.py
[2024-05-10T16:07:47.526+0000] {logging_mixin.py:188} INFO - [2024-05-10T16:07:47.510+0000] {dagbag.py:355} ERROR - Failed to import: /opt/airflow/dags/my_first_dag.py
Traceback (most recent call last):
  File "/home/airflow/.local/lib/python3.12/site-packages/airflow/models/dagbag.py", line 351, in parse
    loader.exec_module(new_module)
  File "<frozen importlib._bootstrap_external>", line 995, in exec_module
  File "<frozen importlib._bootstrap>", line 488, in _call_with_frames_removed
  File "/opt/airflow/dags/my_first_dag.py", line 9, in <module>
    with DAG(dag_id  = 'my_first_dag',
         ^^^^^^^^^^^^^^^^^^^^^^^^^^^^^
TypeError: DAG.__init__() got an unexpected keyword argument 'scheduler_interval'
[2024-05-10T16:07:47.534+0000] {processor.py:842} WARNING - No viable dags retrieved from /opt/airflow/dags/my_first_dag.py
[2024-05-10T16:07:47.767+0000] {processor.py:183} INFO - Processing /opt/airflow/dags/my_first_dag.py took 0.706 seconds
[2024-05-10T16:08:18.200+0000] {processor.py:161} INFO - Started process (PID=571) to work on /opt/airflow/dags/my_first_dag.py
[2024-05-10T16:08:18.202+0000] {processor.py:830} INFO - Processing file /opt/airflow/dags/my_first_dag.py for tasks to queue
[2024-05-10T16:08:18.209+0000] {logging_mixin.py:188} INFO - [2024-05-10T16:08:18.208+0000] {dagbag.py:545} INFO - Filling up the DagBag from /opt/airflow/dags/my_first_dag.py
[2024-05-10T16:08:18.226+0000] {logging_mixin.py:188} INFO - [2024-05-10T16:08:18.221+0000] {dagbag.py:355} ERROR - Failed to import: /opt/airflow/dags/my_first_dag.py
Traceback (most recent call last):
  File "/home/airflow/.local/lib/python3.12/site-packages/airflow/models/dagbag.py", line 351, in parse
    loader.exec_module(new_module)
  File "<frozen importlib._bootstrap_external>", line 995, in exec_module
  File "<frozen importlib._bootstrap>", line 488, in _call_with_frames_removed
  File "/opt/airflow/dags/my_first_dag.py", line 9, in <module>
    with DAG(dag_id  = 'my_first_dag',
         ^^^^^^^^^^^^^^^^^^^^^^^^^^^^^
TypeError: DAG.__init__() got an unexpected keyword argument 'scheduler_interval'
[2024-05-10T16:08:18.228+0000] {processor.py:842} WARNING - No viable dags retrieved from /opt/airflow/dags/my_first_dag.py
[2024-05-10T16:08:18.324+0000] {processor.py:183} INFO - Processing /opt/airflow/dags/my_first_dag.py took 0.147 seconds
[2024-05-10T16:08:48.534+0000] {processor.py:161} INFO - Started process (PID=582) to work on /opt/airflow/dags/my_first_dag.py
[2024-05-10T16:08:48.550+0000] {processor.py:830} INFO - Processing file /opt/airflow/dags/my_first_dag.py for tasks to queue
[2024-05-10T16:08:48.555+0000] {logging_mixin.py:188} INFO - [2024-05-10T16:08:48.554+0000] {dagbag.py:545} INFO - Filling up the DagBag from /opt/airflow/dags/my_first_dag.py
[2024-05-10T16:08:48.568+0000] {logging_mixin.py:188} INFO - [2024-05-10T16:08:48.565+0000] {dagbag.py:355} ERROR - Failed to import: /opt/airflow/dags/my_first_dag.py
Traceback (most recent call last):
  File "/home/airflow/.local/lib/python3.12/site-packages/airflow/models/dagbag.py", line 351, in parse
    loader.exec_module(new_module)
  File "<frozen importlib._bootstrap_external>", line 995, in exec_module
  File "<frozen importlib._bootstrap>", line 488, in _call_with_frames_removed
  File "/opt/airflow/dags/my_first_dag.py", line 9, in <module>
    with DAG(dag_id  = 'my_first_dag',
         ^^^^^^^^^^^^^^^^^^^^^^^^^^^^^
TypeError: DAG.__init__() got an unexpected keyword argument 'scheduler_interval'
[2024-05-10T16:08:48.570+0000] {processor.py:842} WARNING - No viable dags retrieved from /opt/airflow/dags/my_first_dag.py
[2024-05-10T16:08:48.613+0000] {processor.py:183} INFO - Processing /opt/airflow/dags/my_first_dag.py took 0.119 seconds
[2024-05-10T16:09:18.945+0000] {processor.py:161} INFO - Started process (PID=592) to work on /opt/airflow/dags/my_first_dag.py
[2024-05-10T16:09:18.946+0000] {processor.py:830} INFO - Processing file /opt/airflow/dags/my_first_dag.py for tasks to queue
[2024-05-10T16:09:18.949+0000] {logging_mixin.py:188} INFO - [2024-05-10T16:09:18.948+0000] {dagbag.py:545} INFO - Filling up the DagBag from /opt/airflow/dags/my_first_dag.py
[2024-05-10T16:09:18.957+0000] {logging_mixin.py:188} INFO - [2024-05-10T16:09:18.955+0000] {dagbag.py:355} ERROR - Failed to import: /opt/airflow/dags/my_first_dag.py
Traceback (most recent call last):
  File "/home/airflow/.local/lib/python3.12/site-packages/airflow/models/dagbag.py", line 351, in parse
    loader.exec_module(new_module)
  File "<frozen importlib._bootstrap_external>", line 995, in exec_module
  File "<frozen importlib._bootstrap>", line 488, in _call_with_frames_removed
  File "/opt/airflow/dags/my_first_dag.py", line 9, in <module>
    with DAG(dag_id  = 'my_first_dag',
         ^^^^^^^^^^^^^^^^^^^^^^^^^^^^^
TypeError: DAG.__init__() got an unexpected keyword argument 'scheduler_interval'
[2024-05-10T16:09:18.959+0000] {processor.py:842} WARNING - No viable dags retrieved from /opt/airflow/dags/my_first_dag.py
[2024-05-10T16:09:18.987+0000] {processor.py:183} INFO - Processing /opt/airflow/dags/my_first_dag.py took 0.051 seconds
[2024-05-10T16:09:27.034+0000] {processor.py:161} INFO - Started process (PID=597) to work on /opt/airflow/dags/my_first_dag.py
[2024-05-10T16:09:27.035+0000] {processor.py:830} INFO - Processing file /opt/airflow/dags/my_first_dag.py for tasks to queue
[2024-05-10T16:09:27.038+0000] {logging_mixin.py:188} INFO - [2024-05-10T16:09:27.037+0000] {dagbag.py:545} INFO - Filling up the DagBag from /opt/airflow/dags/my_first_dag.py
[2024-05-10T16:09:27.051+0000] {logging_mixin.py:188} INFO - [2024-05-10T16:09:27.048+0000] {dagbag.py:355} ERROR - Failed to import: /opt/airflow/dags/my_first_dag.py
Traceback (most recent call last):
  File "/home/airflow/.local/lib/python3.12/site-packages/airflow/models/dagbag.py", line 351, in parse
    loader.exec_module(new_module)
  File "<frozen importlib._bootstrap_external>", line 995, in exec_module
  File "<frozen importlib._bootstrap>", line 488, in _call_with_frames_removed
  File "/opt/airflow/dags/my_first_dag.py", line 9, in <module>
    with DAG(dag_id  = 'my_first_dag',
         ^^^^^^^^^^^^^^^^^^^^^^^^^^^^^
TypeError: DAG.__init__() got an unexpected keyword argument 'scheduler_interval'
[2024-05-10T16:09:27.055+0000] {processor.py:842} WARNING - No viable dags retrieved from /opt/airflow/dags/my_first_dag.py
[2024-05-10T16:09:27.089+0000] {processor.py:183} INFO - Processing /opt/airflow/dags/my_first_dag.py took 0.065 seconds
[2024-05-10T16:09:57.353+0000] {processor.py:161} INFO - Started process (PID=608) to work on /opt/airflow/dags/my_first_dag.py
[2024-05-10T16:09:57.355+0000] {processor.py:830} INFO - Processing file /opt/airflow/dags/my_first_dag.py for tasks to queue
[2024-05-10T16:09:57.359+0000] {logging_mixin.py:188} INFO - [2024-05-10T16:09:57.358+0000] {dagbag.py:545} INFO - Filling up the DagBag from /opt/airflow/dags/my_first_dag.py
[2024-05-10T16:09:57.371+0000] {logging_mixin.py:188} INFO - [2024-05-10T16:09:57.369+0000] {dagbag.py:355} ERROR - Failed to import: /opt/airflow/dags/my_first_dag.py
Traceback (most recent call last):
  File "/home/airflow/.local/lib/python3.12/site-packages/airflow/models/dagbag.py", line 351, in parse
    loader.exec_module(new_module)
  File "<frozen importlib._bootstrap_external>", line 995, in exec_module
  File "<frozen importlib._bootstrap>", line 488, in _call_with_frames_removed
  File "/opt/airflow/dags/my_first_dag.py", line 9, in <module>
    with DAG(dag_id  = 'my_first_dag',
         ^^^^^^^^^^^^^^^^^^^^^^^^^^^^^
TypeError: DAG.__init__() got an unexpected keyword argument 'scheduler_interval'
[2024-05-10T16:09:57.372+0000] {processor.py:842} WARNING - No viable dags retrieved from /opt/airflow/dags/my_first_dag.py
[2024-05-10T16:09:57.406+0000] {processor.py:183} INFO - Processing /opt/airflow/dags/my_first_dag.py took 0.065 seconds
[2024-05-10T16:10:27.637+0000] {processor.py:161} INFO - Started process (PID=619) to work on /opt/airflow/dags/my_first_dag.py
[2024-05-10T16:10:27.639+0000] {processor.py:830} INFO - Processing file /opt/airflow/dags/my_first_dag.py for tasks to queue
[2024-05-10T16:10:27.641+0000] {logging_mixin.py:188} INFO - [2024-05-10T16:10:27.641+0000] {dagbag.py:545} INFO - Filling up the DagBag from /opt/airflow/dags/my_first_dag.py
[2024-05-10T16:10:27.648+0000] {logging_mixin.py:188} INFO - [2024-05-10T16:10:27.646+0000] {dagbag.py:355} ERROR - Failed to import: /opt/airflow/dags/my_first_dag.py
Traceback (most recent call last):
  File "/home/airflow/.local/lib/python3.12/site-packages/airflow/models/dagbag.py", line 351, in parse
    loader.exec_module(new_module)
  File "<frozen importlib._bootstrap_external>", line 995, in exec_module
  File "<frozen importlib._bootstrap>", line 488, in _call_with_frames_removed
  File "/opt/airflow/dags/my_first_dag.py", line 9, in <module>
    with DAG(dag_id  = 'my_first_dag',
         ^^^^^^^^^^^^^^^^^^^^^^^^^^^^^
TypeError: DAG.__init__() got an unexpected keyword argument 'scheduler_interval'
[2024-05-10T16:10:27.650+0000] {processor.py:842} WARNING - No viable dags retrieved from /opt/airflow/dags/my_first_dag.py
[2024-05-10T16:10:27.678+0000] {processor.py:183} INFO - Processing /opt/airflow/dags/my_first_dag.py took 0.050 seconds
[2024-05-10T16:10:41.839+0000] {processor.py:161} INFO - Started process (PID=629) to work on /opt/airflow/dags/my_first_dag.py
[2024-05-10T16:10:41.840+0000] {processor.py:830} INFO - Processing file /opt/airflow/dags/my_first_dag.py for tasks to queue
[2024-05-10T16:10:41.843+0000] {logging_mixin.py:188} INFO - [2024-05-10T16:10:41.843+0000] {dagbag.py:545} INFO - Filling up the DagBag from /opt/airflow/dags/my_first_dag.py
[2024-05-10T16:10:41.856+0000] {logging_mixin.py:188} INFO - [2024-05-10T16:10:41.853+0000] {dagbag.py:355} ERROR - Failed to import: /opt/airflow/dags/my_first_dag.py
Traceback (most recent call last):
  File "/home/airflow/.local/lib/python3.12/site-packages/airflow/models/dagbag.py", line 351, in parse
    loader.exec_module(new_module)
  File "<frozen importlib._bootstrap_external>", line 995, in exec_module
  File "<frozen importlib._bootstrap>", line 488, in _call_with_frames_removed
  File "/opt/airflow/dags/my_first_dag.py", line 9, in <module>
    with DAG(dag_id  = 'my_first_dag',
         ^^^^^^^^^^^^^^^^^^^^^^^^^^^^^
TypeError: DAG.__init__() got an unexpected keyword argument 'scheduler_interval'
[2024-05-10T16:10:41.857+0000] {processor.py:842} WARNING - No viable dags retrieved from /opt/airflow/dags/my_first_dag.py
[2024-05-10T16:10:41.903+0000] {processor.py:183} INFO - Processing /opt/airflow/dags/my_first_dag.py took 0.074 seconds
[2024-05-10T16:11:12.197+0000] {processor.py:161} INFO - Started process (PID=640) to work on /opt/airflow/dags/my_first_dag.py
[2024-05-10T16:11:12.198+0000] {processor.py:830} INFO - Processing file /opt/airflow/dags/my_first_dag.py for tasks to queue
[2024-05-10T16:11:12.201+0000] {logging_mixin.py:188} INFO - [2024-05-10T16:11:12.201+0000] {dagbag.py:545} INFO - Filling up the DagBag from /opt/airflow/dags/my_first_dag.py
[2024-05-10T16:11:12.210+0000] {logging_mixin.py:188} INFO - [2024-05-10T16:11:12.207+0000] {dagbag.py:355} ERROR - Failed to import: /opt/airflow/dags/my_first_dag.py
Traceback (most recent call last):
  File "/home/airflow/.local/lib/python3.12/site-packages/airflow/models/dagbag.py", line 351, in parse
    loader.exec_module(new_module)
  File "<frozen importlib._bootstrap_external>", line 995, in exec_module
  File "<frozen importlib._bootstrap>", line 488, in _call_with_frames_removed
  File "/opt/airflow/dags/my_first_dag.py", line 9, in <module>
    with DAG(dag_id  = 'my_first_dag',
         ^^^^^^^^^^^^^^^^^^^^^^^^^^^^^
TypeError: DAG.__init__() got an unexpected keyword argument 'scheduler_interval'
[2024-05-10T16:11:12.211+0000] {processor.py:842} WARNING - No viable dags retrieved from /opt/airflow/dags/my_first_dag.py
[2024-05-10T16:11:12.238+0000] {processor.py:183} INFO - Processing /opt/airflow/dags/my_first_dag.py took 0.049 seconds
[2024-05-10T16:11:31.348+0000] {processor.py:161} INFO - Started process (PID=645) to work on /opt/airflow/dags/my_first_dag.py
[2024-05-10T16:11:31.351+0000] {processor.py:830} INFO - Processing file /opt/airflow/dags/my_first_dag.py for tasks to queue
[2024-05-10T16:11:31.354+0000] {logging_mixin.py:188} INFO - [2024-05-10T16:11:31.353+0000] {dagbag.py:545} INFO - Filling up the DagBag from /opt/airflow/dags/my_first_dag.py
[2024-05-10T16:11:31.367+0000] {logging_mixin.py:188} INFO - [2024-05-10T16:11:31.364+0000] {dagbag.py:355} ERROR - Failed to import: /opt/airflow/dags/my_first_dag.py
Traceback (most recent call last):
  File "/home/airflow/.local/lib/python3.12/site-packages/airflow/models/dagbag.py", line 351, in parse
    loader.exec_module(new_module)
  File "<frozen importlib._bootstrap_external>", line 995, in exec_module
  File "<frozen importlib._bootstrap>", line 488, in _call_with_frames_removed
  File "/opt/airflow/dags/my_first_dag.py", line 9, in <module>
    with DAG(dag_id  = 'my_first_dag',
         ^^^^^^^^^^^^^^^^^^^^^^^^^^^^^
TypeError: DAG.__init__() got an unexpected keyword argument 'scheduler_interval'
[2024-05-10T16:11:31.368+0000] {processor.py:842} WARNING - No viable dags retrieved from /opt/airflow/dags/my_first_dag.py
[2024-05-10T16:11:31.404+0000] {processor.py:183} INFO - Processing /opt/airflow/dags/my_first_dag.py took 0.065 seconds
[2024-05-10T16:11:33.407+0000] {processor.py:161} INFO - Started process (PID=650) to work on /opt/airflow/dags/my_first_dag.py
[2024-05-10T16:11:33.413+0000] {processor.py:830} INFO - Processing file /opt/airflow/dags/my_first_dag.py for tasks to queue
[2024-05-10T16:11:33.417+0000] {logging_mixin.py:188} INFO - [2024-05-10T16:11:33.417+0000] {dagbag.py:545} INFO - Filling up the DagBag from /opt/airflow/dags/my_first_dag.py
[2024-05-10T16:11:33.438+0000] {logging_mixin.py:188} INFO - [2024-05-10T16:11:33.426+0000] {dagbag.py:355} ERROR - Failed to import: /opt/airflow/dags/my_first_dag.py
Traceback (most recent call last):
  File "/home/airflow/.local/lib/python3.12/site-packages/airflow/models/dagbag.py", line 351, in parse
    loader.exec_module(new_module)
  File "<frozen importlib._bootstrap_external>", line 995, in exec_module
  File "<frozen importlib._bootstrap>", line 488, in _call_with_frames_removed
  File "/opt/airflow/dags/my_first_dag.py", line 9, in <module>
    with DAG(dag_id  = 'my_first_dag',
         ^^^^^^^^^^^^^^^^^^^^^^^^^^^^^
TypeError: DAG.__init__() got an unexpected keyword argument 'scheduler_interval'
[2024-05-10T16:11:33.447+0000] {processor.py:842} WARNING - No viable dags retrieved from /opt/airflow/dags/my_first_dag.py
[2024-05-10T16:11:33.529+0000] {processor.py:183} INFO - Processing /opt/airflow/dags/my_first_dag.py took 0.133 seconds
[2024-05-10T16:12:03.941+0000] {processor.py:161} INFO - Started process (PID=661) to work on /opt/airflow/dags/my_first_dag.py
[2024-05-10T16:12:03.945+0000] {processor.py:830} INFO - Processing file /opt/airflow/dags/my_first_dag.py for tasks to queue
[2024-05-10T16:12:03.951+0000] {logging_mixin.py:188} INFO - [2024-05-10T16:12:03.950+0000] {dagbag.py:545} INFO - Filling up the DagBag from /opt/airflow/dags/my_first_dag.py
[2024-05-10T16:12:03.970+0000] {logging_mixin.py:188} INFO - [2024-05-10T16:12:03.965+0000] {dagbag.py:355} ERROR - Failed to import: /opt/airflow/dags/my_first_dag.py
Traceback (most recent call last):
  File "/home/airflow/.local/lib/python3.12/site-packages/airflow/models/dagbag.py", line 351, in parse
    loader.exec_module(new_module)
  File "<frozen importlib._bootstrap_external>", line 995, in exec_module
  File "<frozen importlib._bootstrap>", line 488, in _call_with_frames_removed
  File "/opt/airflow/dags/my_first_dag.py", line 9, in <module>
    with DAG(dag_id  = 'my_first_dag',
         ^^^^^^^^^^^^^^^^^^^^^^^^^^^^^
TypeError: DAG.__init__() got an unexpected keyword argument 'scheduler_interval'
[2024-05-10T16:12:03.973+0000] {processor.py:842} WARNING - No viable dags retrieved from /opt/airflow/dags/my_first_dag.py
[2024-05-10T16:12:04.038+0000] {processor.py:183} INFO - Processing /opt/airflow/dags/my_first_dag.py took 0.132 seconds
[2024-05-10T16:12:34.325+0000] {processor.py:161} INFO - Started process (PID=671) to work on /opt/airflow/dags/my_first_dag.py
[2024-05-10T16:12:34.340+0000] {processor.py:830} INFO - Processing file /opt/airflow/dags/my_first_dag.py for tasks to queue
[2024-05-10T16:12:34.346+0000] {logging_mixin.py:188} INFO - [2024-05-10T16:12:34.344+0000] {dagbag.py:545} INFO - Filling up the DagBag from /opt/airflow/dags/my_first_dag.py
[2024-05-10T16:12:34.366+0000] {logging_mixin.py:188} INFO - [2024-05-10T16:12:34.361+0000] {dagbag.py:355} ERROR - Failed to import: /opt/airflow/dags/my_first_dag.py
Traceback (most recent call last):
  File "/home/airflow/.local/lib/python3.12/site-packages/airflow/models/dagbag.py", line 351, in parse
    loader.exec_module(new_module)
  File "<frozen importlib._bootstrap_external>", line 995, in exec_module
  File "<frozen importlib._bootstrap>", line 488, in _call_with_frames_removed
  File "/opt/airflow/dags/my_first_dag.py", line 9, in <module>
    with DAG(dag_id  = 'my_first_dag',
         ^^^^^^^^^^^^^^^^^^^^^^^^^^^^^
TypeError: DAG.__init__() got an unexpected keyword argument 'scheduler_interval'
[2024-05-10T16:12:34.376+0000] {processor.py:842} WARNING - No viable dags retrieved from /opt/airflow/dags/my_first_dag.py
[2024-05-10T16:12:34.461+0000] {processor.py:183} INFO - Processing /opt/airflow/dags/my_first_dag.py took 0.166 seconds
[2024-05-10T16:12:48.216+0000] {processor.py:161} INFO - Started process (PID=681) to work on /opt/airflow/dags/my_first_dag.py
[2024-05-10T16:12:48.253+0000] {processor.py:830} INFO - Processing file /opt/airflow/dags/my_first_dag.py for tasks to queue
[2024-05-10T16:12:48.270+0000] {logging_mixin.py:188} INFO - [2024-05-10T16:12:48.269+0000] {dagbag.py:545} INFO - Filling up the DagBag from /opt/airflow/dags/my_first_dag.py
[2024-05-10T16:12:48.411+0000] {logging_mixin.py:188} INFO - [2024-05-10T16:12:48.408+0000] {dagbag.py:355} ERROR - Failed to import: /opt/airflow/dags/my_first_dag.py
Traceback (most recent call last):
  File "/home/airflow/.local/lib/python3.12/site-packages/airflow/models/dagbag.py", line 351, in parse
    loader.exec_module(new_module)
  File "<frozen importlib._bootstrap_external>", line 995, in exec_module
  File "<frozen importlib._bootstrap>", line 488, in _call_with_frames_removed
  File "/opt/airflow/dags/my_first_dag.py", line 9, in <module>
    with DAG(dag_id  = 'my_first_dag',
         ^^^^^^^^^^^^^^^^^^^^^^^^^^^^^
TypeError: DAG.__init__() got an unexpected keyword argument 'scheduler_interval'
[2024-05-10T16:12:48.442+0000] {processor.py:842} WARNING - No viable dags retrieved from /opt/airflow/dags/my_first_dag.py
[2024-05-10T16:12:48.650+0000] {processor.py:183} INFO - Processing /opt/airflow/dags/my_first_dag.py took 0.467 seconds
[2024-05-10T16:13:18.435+0000] {processor.py:161} INFO - Started process (PID=692) to work on /opt/airflow/dags/my_first_dag.py
[2024-05-10T16:13:18.437+0000] {processor.py:830} INFO - Processing file /opt/airflow/dags/my_first_dag.py for tasks to queue
[2024-05-10T16:13:18.442+0000] {logging_mixin.py:188} INFO - [2024-05-10T16:13:18.441+0000] {dagbag.py:545} INFO - Filling up the DagBag from /opt/airflow/dags/my_first_dag.py
[2024-05-10T16:13:18.457+0000] {logging_mixin.py:188} INFO - [2024-05-10T16:13:18.455+0000] {dagbag.py:355} ERROR - Failed to import: /opt/airflow/dags/my_first_dag.py
Traceback (most recent call last):
  File "/home/airflow/.local/lib/python3.12/site-packages/airflow/models/dagbag.py", line 351, in parse
    loader.exec_module(new_module)
  File "<frozen importlib._bootstrap_external>", line 995, in exec_module
  File "<frozen importlib._bootstrap>", line 488, in _call_with_frames_removed
  File "/opt/airflow/dags/my_first_dag.py", line 2, in <module>
    from airflow.operator.bash import DAG
ModuleNotFoundError: No module named 'airflow.operator'
[2024-05-10T16:13:18.459+0000] {processor.py:842} WARNING - No viable dags retrieved from /opt/airflow/dags/my_first_dag.py
[2024-05-10T16:13:18.499+0000] {processor.py:183} INFO - Processing /opt/airflow/dags/my_first_dag.py took 0.076 seconds
[2024-05-10T16:13:28.553+0000] {processor.py:161} INFO - Started process (PID=697) to work on /opt/airflow/dags/my_first_dag.py
[2024-05-10T16:13:28.556+0000] {processor.py:830} INFO - Processing file /opt/airflow/dags/my_first_dag.py for tasks to queue
[2024-05-10T16:13:28.559+0000] {logging_mixin.py:188} INFO - [2024-05-10T16:13:28.558+0000] {dagbag.py:545} INFO - Filling up the DagBag from /opt/airflow/dags/my_first_dag.py
[2024-05-10T16:13:28.584+0000] {logging_mixin.py:188} INFO - [2024-05-10T16:13:28.582+0000] {dagbag.py:355} ERROR - Failed to import: /opt/airflow/dags/my_first_dag.py
Traceback (most recent call last):
  File "/home/airflow/.local/lib/python3.12/site-packages/airflow/models/dagbag.py", line 351, in parse
    loader.exec_module(new_module)
  File "<frozen importlib._bootstrap_external>", line 995, in exec_module
  File "<frozen importlib._bootstrap>", line 488, in _call_with_frames_removed
  File "/opt/airflow/dags/my_first_dag.py", line 2, in <module>
    from airflow.operator.bash import BashOperator
ModuleNotFoundError: No module named 'airflow.operator'
[2024-05-10T16:13:28.585+0000] {processor.py:842} WARNING - No viable dags retrieved from /opt/airflow/dags/my_first_dag.py
[2024-05-10T16:13:28.657+0000] {processor.py:183} INFO - Processing /opt/airflow/dags/my_first_dag.py took 0.120 seconds
[2024-05-10T16:13:42.796+0000] {processor.py:161} INFO - Started process (PID=708) to work on /opt/airflow/dags/my_first_dag.py
[2024-05-10T16:13:42.798+0000] {processor.py:830} INFO - Processing file /opt/airflow/dags/my_first_dag.py for tasks to queue
[2024-05-10T16:13:42.807+0000] {logging_mixin.py:188} INFO - [2024-05-10T16:13:42.805+0000] {dagbag.py:545} INFO - Filling up the DagBag from /opt/airflow/dags/my_first_dag.py
[2024-05-10T16:13:42.832+0000] {logging_mixin.py:188} INFO - [2024-05-10T16:13:42.829+0000] {dagbag.py:355} ERROR - Failed to import: /opt/airflow/dags/my_first_dag.py
Traceback (most recent call last):
  File "/home/airflow/.local/lib/python3.12/site-packages/airflow/models/dagbag.py", line 351, in parse
    loader.exec_module(new_module)
  File "<frozen importlib._bootstrap_external>", line 995, in exec_module
  File "<frozen importlib._bootstrap>", line 488, in _call_with_frames_removed
  File "/opt/airflow/dags/my_first_dag.py", line 2, in <module>
    from airflow.operator.bash import BashOperator
ModuleNotFoundError: No module named 'airflow.operator'
[2024-05-10T16:13:42.846+0000] {processor.py:842} WARNING - No viable dags retrieved from /opt/airflow/dags/my_first_dag.py
[2024-05-10T16:13:43.389+0000] {processor.py:183} INFO - Processing /opt/airflow/dags/my_first_dag.py took 0.609 seconds
[2024-05-10T16:14:03.139+0000] {processor.py:161} INFO - Started process (PID=713) to work on /opt/airflow/dags/my_first_dag.py
[2024-05-10T16:14:03.141+0000] {processor.py:830} INFO - Processing file /opt/airflow/dags/my_first_dag.py for tasks to queue
[2024-05-10T16:14:03.144+0000] {logging_mixin.py:188} INFO - [2024-05-10T16:14:03.143+0000] {dagbag.py:545} INFO - Filling up the DagBag from /opt/airflow/dags/my_first_dag.py
[2024-05-10T16:14:03.159+0000] {logging_mixin.py:188} INFO - [2024-05-10T16:14:03.157+0000] {dagbag.py:355} ERROR - Failed to import: /opt/airflow/dags/my_first_dag.py
Traceback (most recent call last):
  File "/home/airflow/.local/lib/python3.12/site-packages/airflow/models/dagbag.py", line 351, in parse
    loader.exec_module(new_module)
  File "<frozen importlib._bootstrap_external>", line 995, in exec_module
  File "<frozen importlib._bootstrap>", line 488, in _call_with_frames_removed
  File "/opt/airflow/dags/my_first_dag.py", line 2, in <module>
    from airflow.operator.bash import BashOperator
ModuleNotFoundError: No module named 'airflow.operator'
[2024-05-10T16:14:03.160+0000] {processor.py:842} WARNING - No viable dags retrieved from /opt/airflow/dags/my_first_dag.py
[2024-05-10T16:14:03.194+0000] {processor.py:183} INFO - Processing /opt/airflow/dags/my_first_dag.py took 0.064 seconds
[2024-05-10T16:14:05.168+0000] {processor.py:161} INFO - Started process (PID=718) to work on /opt/airflow/dags/my_first_dag.py
[2024-05-10T16:14:05.169+0000] {processor.py:830} INFO - Processing file /opt/airflow/dags/my_first_dag.py for tasks to queue
[2024-05-10T16:14:05.172+0000] {logging_mixin.py:188} INFO - [2024-05-10T16:14:05.172+0000] {dagbag.py:545} INFO - Filling up the DagBag from /opt/airflow/dags/my_first_dag.py
[2024-05-10T16:14:05.184+0000] {logging_mixin.py:188} INFO - [2024-05-10T16:14:05.182+0000] {dagbag.py:355} ERROR - Failed to import: /opt/airflow/dags/my_first_dag.py
Traceback (most recent call last):
  File "/home/airflow/.local/lib/python3.12/site-packages/airflow/models/dagbag.py", line 351, in parse
    loader.exec_module(new_module)
  File "<frozen importlib._bootstrap_external>", line 995, in exec_module
  File "<frozen importlib._bootstrap>", line 488, in _call_with_frames_removed
  File "/opt/airflow/dags/my_first_dag.py", line 2, in <module>
    from airflow.operator.bash import BashOperator
ModuleNotFoundError: No module named 'airflow.operator'
[2024-05-10T16:14:05.187+0000] {processor.py:842} WARNING - No viable dags retrieved from /opt/airflow/dags/my_first_dag.py
[2024-05-10T16:14:05.254+0000] {processor.py:183} INFO - Processing /opt/airflow/dags/my_first_dag.py took 0.099 seconds
[2024-05-10T16:14:26.490+0000] {processor.py:161} INFO - Started process (PID=728) to work on /opt/airflow/dags/my_first_dag.py
[2024-05-10T16:14:26.492+0000] {processor.py:830} INFO - Processing file /opt/airflow/dags/my_first_dag.py for tasks to queue
[2024-05-10T16:14:26.495+0000] {logging_mixin.py:188} INFO - [2024-05-10T16:14:26.494+0000] {dagbag.py:545} INFO - Filling up the DagBag from /opt/airflow/dags/my_first_dag.py
[2024-05-10T16:14:26.507+0000] {logging_mixin.py:188} INFO - [2024-05-10T16:14:26.505+0000] {dagbag.py:355} ERROR - Failed to import: /opt/airflow/dags/my_first_dag.py
Traceback (most recent call last):
  File "/home/airflow/.local/lib/python3.12/site-packages/airflow/models/dagbag.py", line 351, in parse
    loader.exec_module(new_module)
  File "<frozen importlib._bootstrap_external>", line 995, in exec_module
  File "<frozen importlib._bootstrap>", line 488, in _call_with_frames_removed
  File "/opt/airflow/dags/my_first_dag.py", line 2, in <module>
    from airflow.operator.bash import BashOperator
ModuleNotFoundError: No module named 'airflow.operator'
[2024-05-10T16:14:26.508+0000] {processor.py:842} WARNING - No viable dags retrieved from /opt/airflow/dags/my_first_dag.py
[2024-05-10T16:14:26.541+0000] {processor.py:183} INFO - Processing /opt/airflow/dags/my_first_dag.py took 0.060 seconds
[2024-05-10T16:14:57.491+0000] {processor.py:161} INFO - Started process (PID=738) to work on /opt/airflow/dags/my_first_dag.py
[2024-05-10T16:14:57.497+0000] {processor.py:830} INFO - Processing file /opt/airflow/dags/my_first_dag.py for tasks to queue
[2024-05-10T16:14:57.506+0000] {logging_mixin.py:188} INFO - [2024-05-10T16:14:57.504+0000] {dagbag.py:545} INFO - Filling up the DagBag from /opt/airflow/dags/my_first_dag.py
[2024-05-10T16:14:57.539+0000] {logging_mixin.py:188} INFO - [2024-05-10T16:14:57.522+0000] {dagbag.py:355} ERROR - Failed to import: /opt/airflow/dags/my_first_dag.py
Traceback (most recent call last):
  File "/home/airflow/.local/lib/python3.12/site-packages/airflow/models/dagbag.py", line 351, in parse
    loader.exec_module(new_module)
  File "<frozen importlib._bootstrap_external>", line 995, in exec_module
  File "<frozen importlib._bootstrap>", line 488, in _call_with_frames_removed
  File "/opt/airflow/dags/my_first_dag.py", line 2, in <module>
    from airflow.operator.bash import BashOperator
ModuleNotFoundError: No module named 'airflow.operator'
[2024-05-10T16:14:57.550+0000] {processor.py:842} WARNING - No viable dags retrieved from /opt/airflow/dags/my_first_dag.py
[2024-05-10T16:14:57.674+0000] {processor.py:183} INFO - Processing /opt/airflow/dags/my_first_dag.py took 0.209 seconds
[2024-05-10T16:15:06.036+0000] {processor.py:161} INFO - Started process (PID=743) to work on /opt/airflow/dags/my_first_dag.py
[2024-05-10T16:15:06.040+0000] {processor.py:830} INFO - Processing file /opt/airflow/dags/my_first_dag.py for tasks to queue
[2024-05-10T16:15:06.053+0000] {logging_mixin.py:188} INFO - [2024-05-10T16:15:06.052+0000] {dagbag.py:545} INFO - Filling up the DagBag from /opt/airflow/dags/my_first_dag.py
[2024-05-10T16:15:06.072+0000] {logging_mixin.py:188} INFO - [2024-05-10T16:15:06.067+0000] {dagbag.py:355} ERROR - Failed to import: /opt/airflow/dags/my_first_dag.py
Traceback (most recent call last):
  File "/home/airflow/.local/lib/python3.12/site-packages/airflow/models/dagbag.py", line 351, in parse
    loader.exec_module(new_module)
  File "<frozen importlib._bootstrap_external>", line 995, in exec_module
  File "<frozen importlib._bootstrap>", line 488, in _call_with_frames_removed
  File "/opt/airflow/dags/my_first_dag.py", line 10, in <module>
    with DAG(dag_id  = 'my_first_dag',
         ^^^^^^^^^^^^^^^^^^^^^^^^^^^^^
TypeError: DAG.__init__() got an unexpected keyword argument 'scheduler_interval'
[2024-05-10T16:15:06.073+0000] {processor.py:842} WARNING - No viable dags retrieved from /opt/airflow/dags/my_first_dag.py
[2024-05-10T16:15:06.244+0000] {processor.py:183} INFO - Processing /opt/airflow/dags/my_first_dag.py took 0.233 seconds
[2024-05-10T16:15:18.992+0000] {processor.py:161} INFO - Started process (PID=753) to work on /opt/airflow/dags/my_first_dag.py
[2024-05-10T16:15:18.994+0000] {processor.py:830} INFO - Processing file /opt/airflow/dags/my_first_dag.py for tasks to queue
[2024-05-10T16:15:19.000+0000] {logging_mixin.py:188} INFO - [2024-05-10T16:15:18.998+0000] {dagbag.py:545} INFO - Filling up the DagBag from /opt/airflow/dags/my_first_dag.py
[2024-05-10T16:15:19.018+0000] {logging_mixin.py:188} INFO - [2024-05-10T16:15:19.011+0000] {dagbag.py:355} ERROR - Failed to import: /opt/airflow/dags/my_first_dag.py
Traceback (most recent call last):
  File "/home/airflow/.local/lib/python3.12/site-packages/airflow/models/dagbag.py", line 351, in parse
    loader.exec_module(new_module)
  File "<frozen importlib._bootstrap_external>", line 995, in exec_module
  File "<frozen importlib._bootstrap>", line 488, in _call_with_frames_removed
  File "/opt/airflow/dags/my_first_dag.py", line 10, in <module>
    with DAG(dag_id  = 'my_first_dag',
         ^^^^^^^^^^^^^^^^^^^^^^^^^^^^^
TypeError: DAG.__init__() got an unexpected keyword argument 'scheduler_interval'
[2024-05-10T16:15:19.019+0000] {processor.py:842} WARNING - No viable dags retrieved from /opt/airflow/dags/my_first_dag.py
[2024-05-10T16:15:19.066+0000] {processor.py:183} INFO - Processing /opt/airflow/dags/my_first_dag.py took 0.088 seconds
