[2024-05-11T12:34:16.671+0000] {task_context_logger.py:104} ERROR - Executor reports task instance <TaskInstance: python_test_dag_v04.greet scheduled__2024-05-09T00:00:00+00:00 [queued]> finished (failed) although the task says it's queued. (Info: None) Was the task killed externally?
